<?xml version="1.0" ?>
<robot name="gantry_robot_combined">
  <!-- Gantry Axis -->

  <link name="gantry_base_link">
    <collision>
      <geometry>
        <mesh filename="meshes/collision/base_link.obj"/>
      </geometry>
    </collision>
    <visual>
      <geometry>
        <mesh filename="meshes/visual/base_link.obj"/>
      </geometry>
    </visual>
  </link>

  <link name="gantry_slider_link">
    <collision>
      <geometry>
        <mesh filename="meshes/collision/link_1.obj"/>
      </geometry>
    </collision>
    <visual>
      <geometry>
        <mesh filename="meshes/visual/link_1.obj"/>
      </geometry>
    </visual>
  </link>

  <joint name="gantry_slide" type="prismatic">
    <origin xyz="0 0 0" rpy="0 0 0"/>
    <parent link="gantry_base_link"/>
    <child link="gantry_slider_link"/>
    <axis xyz="1 0 0"/>
    <limit effort="1000" lower="-0.41" upper="7.3" velocity="1.0"/>
  </joint>

  <!-- ABB Robot (renamed links) -->

  <link name="robot_base_link">
    <collision>
      <geometry>
        <mesh filename="meshes/collision/base_link 2.obj"/>
      </geometry>
    </collision>
    <visual>
      <geometry>
        <mesh filename="meshes/visual/base_link 2.obj"/>
      </geometry>
    </visual>
  </link>

  <link name="robot_link_1">
    <collision>
      <geometry>
        <mesh filename="meshes/collision/link_1 2.obj"/>
      </geometry>
    </collision>
    <visual>
      <geometry>
        <mesh filename="meshes/visual/link_1 2.obj"/>
      </geometry>
    </visual>
  </link>

  <link name="robot_link_2">
    <collision>
      <geometry>
        <mesh filename="meshes/collision/link_2.obj"/>
      </geometry>
    </collision>
    <visual>
      <geometry>
        <mesh filename="meshes/visual/link_2.obj"/>
      </geometry>
    </visual>
  </link>

  <link name="robot_link_3">
    <collision>
      <geometry>
        <mesh filename="meshes/collision/link_3.obj"/>
      </geometry>
    </collision>
    <visual>
      <geometry>
        <mesh filename="meshes/visual/link_3.obj"/>
      </geometry>
    </visual>
  </link>

  <link name="robot_link_4">
    <collision>
      <geometry>
        <mesh filename="meshes/collision/link_4.obj"/>
      </geometry>
    </collision>
    <visual>
      <geometry>
        <mesh filename="meshes/visual/link_4.obj"/>
      </geometry>
    </visual>
  </link>

  <link name="robot_link_5">
    <collision>
      <geometry>
        <mesh filename="meshes/collision/link_5.obj"/>
      </geometry>
    </collision>
    <visual>
      <geometry>
        <mesh filename="meshes/visual/link_5.obj"/>
      </geometry>
    </visual>
  </link>

  <link name="robot_link_6">
    <collision>
      <geometry>
        <mesh filename="meshes/collision/link_6.obj"/>
      </geometry>
    </collision>
    <visual>
      <geometry>
        <mesh filename="meshes/visual/link_6.obj"/>
      </geometry>
    </visual>
  </link>

  <link name="flange"/>

  <!-- Joint from gantry to ABB base -->
  <joint name="gantry_to_robot_base" type="fixed">
    <origin xyz="0.6 0.43 0.55" rpy="0 0 0"/>
    <parent link="gantry_slider_link"/>
    <child link="robot_base_link"/>
  </joint>

  <!-- ABB joints (renamed) -->
  <joint name="joint_1" type="revolute">
    <origin xyz="0 0 0.780" rpy="0 0 0"/>
    <parent link="robot_base_link"/>
    <child link="robot_link_1"/>
    <axis xyz="0 0 1"/>
    <limit lower="-2.967" upper="2.967" effort="0" velocity="1.745"/>
  </joint>

  <joint name="joint_2" type="revolute">
    <origin xyz="0.320 0 0" rpy="0 0 0"/>
    <parent link="robot_link_1"/>
    <child link="robot_link_2"/>
    <axis xyz="0 1 0"/>
    <limit lower="-1.134" upper="1.484" effort="0" velocity="1.571"/>
  </joint>

  <joint name="joint_3" type="revolute">
    <origin xyz="0 0 1.280" rpy="0 0 0"/>
    <parent link="robot_link_2"/>
    <child link="robot_link_3"/>
    <axis xyz="0 1 0"/>
    <limit lower="-3.142" upper="1.222" effort="0" velocity="1.571"/>
  </joint>

  <joint name="joint_4" type="revolute">
    <origin xyz="0 0 0.200" rpy="0 0 0"/>
    <parent link="robot_link_3"/>
    <child link="robot_link_4"/>
    <axis xyz="1 0 0"/>
    <limit lower="-5.236" upper="5.236" effort="0" velocity="2.967"/>
  </joint>

  <joint name="joint_5" type="revolute">
    <origin xyz="1.5925 0 0" rpy="0 0 0"/>
    <parent link="robot_link_4"/>
    <child link="robot_link_5"/>
    <axis xyz="0 1 0"/>
    <limit lower="-2.269" upper="2.269" effort="0" velocity="2.094"/>
  </joint>

  <joint name="joint_6" type="revolute">
    <origin xyz="0.200 0 0" rpy="0 0 0"/>
    <parent link="robot_link_5"/>
    <child link="robot_link_6"/>
    <axis xyz="1 0 0"/>
    <limit lower="-6.283" upper="6.283" effort="0" velocity="3.316"/>
  </joint>

  <joint name="joint_6-flange" type="fixed">
    <origin xyz="0 0 0" rpy="0 1.570796 0"/>
    <parent link="robot_link_6"/>
    <child link="flange"/>
  </joint>
</robot>
